<?xml version="1.0" ?>
<!-- =================================================================================== -->
<!-- |    This document was autogenerated by xacro from /home/admin1/ros2_ws/src/my_robot/urdf/my_conveyor_belt.xacro | -->
<!-- |    EDITING THIS FILE BY HAND IS NOT RECOMMENDED                                 | -->
<!-- =================================================================================== -->
<robot name="my_conveyor_belt">
  <!-- Material definitions -->
  <material name="grey">
    <color rgba="0.5 0.5 0.5 1.0"/>
  </material>
  <material name="white">
    <color rgba="1.0 1.0 1.0 1.0"/>
  </material>
  <material name="black">
    <color rgba="0.0 0.0 0.0 1.0"/>
  </material>
  <link name="base_link">
    <visual>
      <geometry>
        <box size="2.0 0.5 0.2"/>
      </geometry>
      <origin rpy="0 0 0" xyz="0 0 0"/>
      <material name="grey"/>
    </visual>
    <collision>
      <geometry>
        <box size="2.0 0.5 0.2"/>
      </geometry>
      <origin rpy="0 0 0" xyz="0 0 0"/>
    </collision>
  </link>
  <link name="axle_0">
    <visual>
      <geometry>
        <sphere radius="0.05"/>
      </geometry>
      <origin rpy="0 0 0" xyz="0 0 0"/>
      <material name="white"/>
    </visual>
    <collision>
      <geometry>
        <sphere radius="0.05"/>
      </geometry>
      <origin rpy="0 0 0" xyz="0 0 0"/>
    </collision>
  </link>
  <joint name="base_to_axle_0" type="fixed">
    <parent link="base_link"/>
    <child link="axle_0"/>
    <origin rpy="0 0 0" xyz="-0.8 0 -0.15000000000000002"/>
  </joint>
  <link name="bar_0">
    <visual>
      <geometry>
        <box size="1.4 0.2 0.1"/>
      </geometry>
      <origin rpy="0 0 0" xyz="0 0 0"/>
      <material name="white"/>
    </visual>
    <collision>
      <geometry>
        <box size="1.4 0.2 0.1"/>
      </geometry>
      <origin rpy="0 0 0" xyz="0 0 0"/>
    </collision>
  </link>
  <joint name="axle_0_to_bar_0" type="revolute">
    <parent link="axle_0"/>
    <child link="bar_0"/>
    <origin rpy="0 0 0" xyz="0.25 0 -0.1"/>
    <axis xyz="0 0 1"/>
    <limit effort="100" lower="0" upper="0.7853981633975" velocity="10"/>
  </joint>
  <link name="axle_1">
    <visual>
      <geometry>
        <sphere radius="0.05"/>
      </geometry>
      <origin rpy="0 0 0" xyz="0 0 0"/>
      <material name="white"/>
    </visual>
    <collision>
      <geometry>
        <sphere radius="0.05"/>
      </geometry>
      <origin rpy="0 0 0" xyz="0 0 0"/>
    </collision>
  </link>
  <joint name="base_to_axle_1" type="fixed">
    <parent link="base_link"/>
    <child link="axle_1"/>
    <origin rpy="0 0 0" xyz="-0.4 0 -0.15000000000000002"/>
  </joint>
  <link name="bar_1">
    <visual>
      <geometry>
        <box size="1.4 0.2 0.1"/>
      </geometry>
      <origin rpy="0 0 0" xyz="0 0 0"/>
      <material name="white"/>
    </visual>
    <collision>
      <geometry>
        <box size="1.4 0.2 0.1"/>
      </geometry>
      <origin rpy="0 0 0" xyz="0 0 0"/>
    </collision>
  </link>
  <joint name="axle_1_to_bar_1" type="revolute">
    <parent link="axle_1"/>
    <child link="bar_1"/>
    <origin rpy="0 0 0" xyz="0.25 0 -0.1"/>
    <axis xyz="0 0 1"/>
    <limit effort="100" lower="0" upper="0.7853981633975" velocity="10"/>
  </joint>
  <link name="axle_2">
    <visual>
      <geometry>
        <sphere radius="0.05"/>
      </geometry>
      <origin rpy="0 0 0" xyz="0 0 0"/>
      <material name="white"/>
    </visual>
    <collision>
      <geometry>
        <sphere radius="0.05"/>
      </geometry>
      <origin rpy="0 0 0" xyz="0 0 0"/>
    </collision>
  </link>
  <joint name="base_to_axle_2" type="fixed">
    <parent link="base_link"/>
    <child link="axle_2"/>
    <origin rpy="0 0 0" xyz="0 0 -0.15000000000000002"/>
  </joint>
  <link name="bar_2">
    <visual>
      <geometry>
        <box size="1.4 0.2 0.1"/>
      </geometry>
      <origin rpy="0 0 0" xyz="0 0 0"/>
      <material name="white"/>
    </visual>
    <collision>
      <geometry>
        <box size="1.4 0.2 0.1"/>
      </geometry>
      <origin rpy="0 0 0" xyz="0 0 0"/>
    </collision>
  </link>
  <joint name="axle_2_to_bar_2" type="revolute">
    <parent link="axle_2"/>
    <child link="bar_2"/>
    <origin rpy="0 0 0" xyz="0.25 0 -0.1"/>
    <axis xyz="0 0 1"/>
    <limit effort="100" lower="0" upper="0.7853981633975" velocity="10"/>
  </joint>
  <link name="axle_3">
    <visual>
      <geometry>
        <sphere radius="0.05"/>
      </geometry>
      <origin rpy="0 0 0" xyz="0 0 0"/>
      <material name="white"/>
    </visual>
    <collision>
      <geometry>
        <sphere radius="0.05"/>
      </geometry>
      <origin rpy="0 0 0" xyz="0 0 0"/>
    </collision>
  </link>
  <joint name="base_to_axle_3" type="fixed">
    <parent link="base_link"/>
    <child link="axle_3"/>
    <origin rpy="0 0 0" xyz="0.4 0 -0.15000000000000002"/>
  </joint>
  <link name="bar_3">
    <visual>
      <geometry>
        <box size="1.4 0.2 0.1"/>
      </geometry>
      <origin rpy="0 0 0" xyz="0 0 0"/>
      <material name="white"/>
    </visual>
    <collision>
      <geometry>
        <box size="1.4 0.2 0.1"/>
      </geometry>
      <origin rpy="0 0 0" xyz="0 0 0"/>
    </collision>
  </link>
  <joint name="axle_3_to_bar_3" type="revolute">
    <parent link="axle_3"/>
    <child link="bar_3"/>
    <origin rpy="0 0 0" xyz="0.25 0 -0.1"/>
    <axis xyz="0 0 1"/>
    <limit effort="100" lower="0" upper="0.7853981633975" velocity="10"/>
  </joint>
</robot>
