<?xml version="1.0"?>
<robot xmlns:xacro="http://www.ros.org/wiki/xacro" name="my_robot">

    <material name="blue">
        <color rgba="0.0 0.0 0.7 1.0"/>
    </material>
    <material name="white">
    <color rgba="1.0 1.0 1.0 1.0"/>
    </material>
    
    <link name="base_link">
        <visual>
            <geometry>
                <cylinder radius="0.2" length="0.7"/>
            </geometry>
            <origin rpy="0.0 0.0 0.0" xyz="0.0 0.0 0.0"/>
            <material name="blue"/>
        </visual>

        <collision>
            <geometry>
                <cylinder radius="0.2" length="0.7"/>
            </geometry>
            <origin rpy="0.0 0.0 0.0" xyz="0.0 0.0 0.0"/>
        </collision>

        <inertial>
            <mass value="10"/>    
            <inertia ixx="1e-3" ixy="0.0" ixz="0.0" iyy="1e-3" iyz="0.0" izz="1e-3"/>
        </inertial>
    </link>

    <link name="right_leg">
        <visual>
            <geometry>
                <box size="0.6 0.1 0.2"/>
            </geometry>
            <origin rpy="0 0 0" xyz="0 0 -0.3"/>
            <material name="white"/>
        </visual>
    </link>

    <joint name="base_to_right_leg" type="continuous">
        <axis rpy="0.0 0.0 0.0" xyz="0 1 0"/>
        <parent link="base_link"/>
        <child link="right_leg"/>
        <origin xyz="0 -0.22 0.25"/>
    </joint>

</robot>